{"name":"golden_ascent","origin":[0,100,0],"blocks":[{"x":-4,"y":0,"z":0,"b":"minecraft:iron_block"},{"x":-3,"y":0,"z":0,"b":"minecraft:iron_block"},{"x":-2,"y":0,"z":0,"b":"minecraft:iron_block"},{"x":-1,"y":0,"z":0,"b":"minecraft:iron_block"},{"x":0,"y":0,"z":0,"b":"minecraft:obsidian"},{"x":1,"y":0,"z":0,"b":"minecraft:gold_block"},{"x":2,"y":0,"z":0,"b":"minecraft:gold_block"},{"x":3,"y":0,"z":0,"b":"minecraft:gold_block"},{"x":4,"y":0,"z":0,"b":"minecraft:gold_block"},{"x":-4,"y":1,"z":-1,"b":"minecraft:iron_block"},{"x":-4,"y":1,"z":0,"b":"minecraft:iron_block"},{"x":-3,"y":1,"z":0,"b":"minecraft:iron_block"},{"x":-2,"y":1,"z":0,"b":"minecraft:iron_block"},{"x":-1,"y":1,"z":0,"b":"minecraft:iron_block"},{"x":0,"y":1,"z":0,"b":"minecraft:obsidian"},{"x":1,"y":1,"z":0,"b":"minecraft:gold_block"},{"x":2,"y":1,"z":0,"b":"minecraft:gold_block"},{"x":3,"y":1,"z":0,"b":"minecraft:gold_block"},{"x":4,"y":1,"z":0,"b":"minecraft:gold_block"},{"x":4,"y":1,"z":1,"b":"minecraft:gold_block"},{"x":-3,"y":2,"z":-2,"b":"minecraft:iron_block"},{"x":-3,"y":2,"z":-1,"b":"minecraft:iron_block"},{"x":-3,"y":2,"z":0,"b":"minecraft:iron_block"},{"x":-2,"y":2,"z":0,"b":"minecraft:iron_block"},{"x":-1,"y":2,"z":0,"b":"minecraft:iron_block"},{"x":0,"y":2,"z":0,"b":"minecraft:obsidian"},{"x":1,"y":2,"z":0,"b":"minecraft:gold_block"},{"x":2,"y":2,"z":0,"b":"minecraft:gold_block"},{"x":3,"y":2,"z":0,"b":"minecraft:gold_block"},{"x":3,"y":2,"z":1,"b":"minecraft:gold_block"},{"x":3,"y":2,"z":2,"b":"minecraft:gold_block"},{"x":-3,"y":3,"z":-3,"b":"minecraft:iron_block"},{"x":-3,"y":3,"z":-2,"b":"minecraft:iron_block"},{"x":-3,"y":3,"z":-1,"b":"minecraft:iron_block"},{"x":-3,"y":3,"z":0,"b":"minecraft:iron_block"},{"x":-2,"y":3,"z":0,"b":"minecraft:iron_block"},{"x":-1,"y":3,"z":0,"b":"minecraft:iron_block"},{"x":0,"y":3,"z":0,"b":"minecraft:obsidian"},{"x":1,"y":3,"z":0,"b":"minecraft:gold_block"},{"x":2,"y":3,"z":0,"b":"minecraft:gold_block"},{"x":3,"y":3,"z":0,"b":"minecraft:gold_block"},{"x":3,"y":3,"z":1,"b":"minecraft:gold_block"},{"x":3,"y":3,"z":2,"b":"minecraft:gold_block"},{"x":3,"y":3,"z":3,"b":"minecraft:gold_block"},{"x":-2,"y":4,"z":-3,"b":"minecraft:iron_block"},{"x":-2,"y":4,"z":-2,"b":"minecraft:iron_block"},{"x":-2,"y":4,"z":-1,"b":"minecraft:iron_block"},{"x":-2,"y":4,"z":0,"b":"minecraft:iron_block"},{"x":-1,"y":4,"z":0,"b":"minecraft:iron_block"},{"x":0,"y":4,"z":0,"b":"minecraft:obsidian"},{"x":1,"y":4,"z":0,"b":"minecraft:gold_block"},{"x":2,"y":4,"z":0,"b":"minecraft:gold_block"},{"x":2,"y":4,"z":1,"b":"minecraft:gold_block"},{"x":2,"y":4,"z":2,"b":"minecraft:gold_block"},{"x":2,"y":4,"z":3,"b":"minecraft:gold_block"},{"x":-1,"y":5,"z":-4,"b":"minecraft:iron_block"},{"x":-1,"y":5,"z":-3,"b":"minecraft:iron_block"},{"x":-1,"y":5,"z":-2,"b":"minecraft:iron_block"},{"x":-1,"y":5,"z":-1,"b":"minecraft:iron_block"},{"x":-1,"y":5,"z":0,"b":"minecraft:iron_block"},{"x":0,"y":5,"z":0,"b":"minecraft:obsidian"},{"x":1,"y":5,"z":0,"b":"minecraft:gold_block"},{"x":1,"y":5,"z":1,"b":"minecraft:gold_block"},{"x":1,"y":5,"z":2,"b":"minecraft:gold_block"},{"x":1,"y":5,"z":3,"b":"minecraft:gold_block"},{"x":1,"y":5,"z":4,"b":"minecraft:gold_block"},{"x":0,"y":6,"z":-4,"b":"minecraft:iron_block"},{"x":0,"y":6,"z":-3,"b":"minecraft:iron_block"},{"x":0,"y":6,"z":-2,"b":"minecraft:iron_block"},{"x":0,"y":6,"z":-1,"b":"minecraft:iron_block"},{"x":0,"y":6,"z":0,"b":"minecraft:obsidian"},{"x":0,"y":6,"z":1,"b":"minecraft:gold_block"},{"x":0,"y":6,"z":2,"b":"minecraft:gold_block"},{"x":0,"y":6,"z":3,"b":"minecraft:gold_block"},{"x":0,"y":6,"z":4,"b":"minecraft:gold_block"},{"x":1,"y":7,"z":-4,"b":"minecraft:iron_block"},{"x":1,"y":7,"z":-3,"b":"minecraft:iron_block"},{"x":1,"y":7,"z":-2,"b":"minecraft:iron_block"},{"x":1,"y":7,"z":-1,"b":"minecraft:iron_block"},{"x":-1,"y":7,"z":0,"b":"minecraft:gold_block"},{"x":0,"y":7,"z":0,"b":"minecraft:obsidian"},{"x":1,"y":7,"z":0,"b":"minecraft:iron_block"},{"x":-1,"y":7,"z":1,"b":"minecraft:gold_block"},{"x":-1,"y":7,"z":2,"b":"minecraft:gold_block"},{"x":-1,"y":7,"z":3,"b":"minecraft:gold_block"},{"x":-1,"y":7,"z":4,"b":"minecraft:gold_block"},{"x":2,"y":8,"z":-3,"b":"minecraft:iron_block"},{"x":2,"y":8,"z":-2,"b":"minecraft:iron_block"},{"x":2,"y":8,"z":-1,"b":"minecraft:iron_block"},{"x":-2,"y":8,"z":0,"b":"minecraft:gold_block"},{"x":-1,"y":8,"z":0,"b":"minecraft:gold_block"},{"x":0,"y":8,"z":0,"b":"minecraft:obsidian"},{"x":1,"y":8,"z":0,"b":"minecraft:iron_block"},{"x":2,"y":8,"z":0,"b":"minecraft:iron_block"},{"x":-2,"y":8,"z":1,"b":"minecraft:gold_block"},{"x":-2,"y":8,"z":2,"b":"minecraft:gold_block"},{"x":-2,"y":8,"z":3,"b":"minecraft:gold_block"},{"x":3,"y":9,"z":-3,"b":"minecraft:iron_block"},{"x":3,"y":9,"z":-2,"b":"minecraft:iron_block"},{"x":3,"y":9,"z":-1,"b":"minecraft:iron_block"},{"x":-3,"y":9,"z":0,"b":"minecraft:gold_block"},{"x":-2,"y":9,"z":0,"b":"minecraft:gold_block"},{"x":-1,"y":9,"z":0,"b":"minecraft:gold_block"},{"x":0,"y":9,"z":0,"b":"minecraft:obsidian"},{"x":1,"y":9,"z":0,"b":"minecraft:iron_block"},{"x":2,"y":9,"z":0,"b":"minecraft:iron_block"},{"x":3,"y":9,"z":0,"b":"minecraft:iron_block"},{"x":-3,"y":9,"z":1,"b":"minecraft:gold_block"},{"x":-3,"y":9,"z":2,"b":"minecraft:gold_block"},{"x":-3,"y":9,"z":3,"b":"minecraft:gold_block"},{"x":3,"y":10,"z":-2,"b":"minecraft:iron_block"},{"x":3,"y":10,"z":-1,"b":"minecraft:iron_block"},{"x":-3,"y":10,"z":0,"b":"minecraft:gold_block"},{"x":-2,"y":10,"z":0,"b":"minecraft:gold_block"},{"x":-1,"y":10,"z":0,"b":"minecraft:gold_block"},{"x":0,"y":10,"z":0,"b":"minecraft:obsidian"},{"x":1,"y":10,"z":0,"b":"minecraft:iron_block"},{"x":2,"y":10,"z":0,"b":"minecraft:iron_block"},{"x":3,"y":10,"z":0,"b":"minecraft:iron_block"},{"x":-3,"y":10,"z":1,"b":"minecraft:gold_block"},{"x":-3,"y":10,"z":2,"b":"minecraft:gold_block"},{"x":4,"y":11,"z":-1,"b":"minecraft:iron_block"},{"x":-4,"y":11,"z":0,"b":"minecraft:gold_block"},{"x":-3,"y":11,"z":0,"b":"minecraft:gold_block"},{"x":-2,"y":11,"z":0,"b":"minecraft:gold_block"},{"x":-1,"y":11,"z":0,"b":"minecraft:gold_block"},{"x":0,"y":11,"z":0,"b":"minecraft:obsidian"},{"x":1,"y":11,"z":0,"b":"minecraft:iron_block"},{"x":2,"y":11,"z":0,"b":"minecraft:iron_block"},{"x":3,"y":11,"z":0,"b":"minecraft:iron_block"},{"x":4,"y":11,"z":0,"b":"minecraft:iron_block"},{"x":-4,"y":11,"z":1,"b":"minecraft:gold_block"},{"x":-4,"y":12,"z":0,"b":"minecraft:gold_block"},{"x":-3,"y":12,"z":0,"b":"minecraft:gold_block"},{"x":-2,"y":12,"z":0,"b":"minecraft:gold_block"},{"x":-1,"y":12,"z":0,"b":"minecraft:gold_block"},{"x":0,"y":12,"z":0,"b":"minecraft:obsidian"},{"x":1,"y":12,"z":0,"b":"minecraft:iron_block"},{"x":2,"y":12,"z":0,"b":"minecraft:iron_block"},{"x":3,"y":12,"z":0,"b":"minecraft:iron_block"},{"x":4,"y":12,"z":0,"b":"minecraft:iron_block"},{"x":-4,"y":13,"z":-1,"b":"minecraft:gold_block"},{"x":-4,"y":13,"z":0,"b":"minecraft:gold_block"},{"x":-3,"y":13,"z":0,"b":"minecraft:gold_block"},{"x":-2,"y":13,"z":0,"b":"minecraft:gold_block"},{"x":-1,"y":13,"z":0,"b":"minecraft:gold_block"},{"x":0,"y":13,"z":0,"b":"minecraft:obsidian"},{"x":1,"y":13,"z":0,"b":"minecraft:iron_block"},{"x":2,"y":13,"z":0,"b":"minecraft:iron_block"},{"x":3,"y":13,"z":0,"b":"minecraft:iron_block"},{"x":4,"y":13,"z":0,"b":"minecraft:iron_block"},{"x":4,"y":13,"z":1,"b":"minecraft:iron_block"},{"x":-3,"y":14,"z":-2,"b":"minecraft:gold_block"},{"x":-3,"y":14,"z":-1,"b":"minecraft:gold_block"},{"x":-3,"y":14,"z":0,"b":"minecraft:gold_block"},{"x":-2,"y":14,"z":0,"b":"minecraft:gold_block"},{"x":-1,"y":14,"z":0,"b":"minecraft:gold_block"},{"x":0,"y":14,"z":0,"b":"minecraft:obsidian"},{"x":1,"y":14,"z":0,"b":"minecraft:iron_block"},{"x":2,"y":14,"z":0,"b":"minecraft:iron_block"},{"x":3,"y":14,"z":0,"b":"minecraft:iron_block"},{"x":3,"y":14,"z":1,"b":"minecraft:iron_block"},{"x":3,"y":14,"z":2,"b":"minecraft:iron_block"},{"x":-3,"y":15,"z":-3,"b":"minecraft:gold_block"},{"x":-3,"y":15,"z":-2,"b":"minecraft:gold_block"},{"x":-3,"y":15,"z":-1,"b":"minecraft:gold_block"},{"x":-3,"y":15,"z":0,"b":"minecraft:gold_block"},{"x":-2,"y":15,"z":0,"b":"minecraft:gold_block"},{"x":-1,"y":15,"z":0,"b":"minecraft:gold_block"},{"x":0,"y":15,"z":0,"b":"minecraft:obsidian"},{"x":1,"y":15,"z":0,"b":"minecraft:iron_block"},{"x":2,"y":15,"z":0,"b":"minecraft:iron_block"},{"x":3,"y":15,"z":0,"b":"minecraft:iron_block"},{"x":3,"y":15,"z":1,"b":"minecraft:iron_block"},{"x":3,"y":15,"z":2,"b":"minecraft:iron_block"},{"x":3,"y":15,"z":3,"b":"minecraft:iron_block"},{"x":-2,"y":16,"z":-3,"b":"minecraft:gold_block"},{"x":-2,"y":16,"z":-2,"b":"minecraft:gold_block"},{"x":-2,"y":16,"z":-1,"b":"minecraft:gold_block"},{"x":-2,"y":16,"z":0,"b":"minecraft:gold_block"},{"x":-1,"y":16,"z":0,"b":"minecraft:gold_block"},{"x":0,"y":16,"z":0,"b":"minecraft:obsidian"},{"x":1,"y":16,"z":0,"b":"minecraft:iron_block"},{"x":2,"y":16,"z":0,"b":"minecraft:iron_block"},{"x":2,"y":16,"z":1,"b":"minecraft:iron_block"},{"x":2,"y":16,"z":2,"b":"minecraft:iron_block"},{"x":2,"y":16,"z":3,"b":"minecraft:iron_block"},{"x":-1,"y":17,"z":-4,"b":"minecraft:gold_block"},{"x":-1,"y":17,"z":-3,"b":"minecraft:gold_block"},{"x":-1,"y":17,"z":-2,"b":"minecraft:gold_block"},{"x":-1,"y":17,"z":-1,"b":"minecraft:gold_block"},{"x":-1,"y":17,"z":0,"b":"minecraft:gold_block"},{"x":0,"y":17,"z":0,"b":"minecraft:obsidian"},{"x":1,"y":17,"z":0,"b":"minecraft:iron_block"},{"x":1,"y":17,"z":1,"b":"minecraft:iron_block"},{"x":1,"y":17,"z":2,"b":"minecraft:iron_block"},{"x":1,"y":17,"z":3,"b":"minecraft:iron_block"},{"x":1,"y":17,"z":4,"b":"minecraft:iron_block"},{"x":0,"y":18,"z":-4,"b":"minecraft:gold_block"},{"x":0,"y":18,"z":-3,"b":"minecraft:gold_block"},{"x":0,"y":18,"z":-2,"b":"minecraft:gold_block"},{"x":0,"y":18,"z":-1,"b":"minecraft:gold_block"},{"x":0,"y":18,"z":0,"b":"minecraft:obsidian"},{"x":0,"y":18,"z":1,"b":"minecraft:iron_block"},{"x":0,"y":18,"z":2,"b":"minecraft:iron_block"},{"x":0,"y":18,"z":3,"b":"minecraft:iron_block"},{"x":0,"y":18,"z":4,"b":"minecraft:iron_block"},{"x":1,"y":19,"z":-4,"b":"minecraft:gold_block"},{"x":1,"y":19,"z":-3,"b":"minecraft:gold_block"},{"x":1,"y":19,"z":-2,"b":"minecraft:gold_block"},{"x":1,"y":19,"z":-1,"b":"minecraft:gold_block"},{"x":-1,"y":19,"z":0,"b":"minecraft:iron_block"},{"x":0,"y":19,"z":0,"b":"minecraft:obsidian"},{"x":1,"y":19,"z":0,"b":"minecraft:gold_block"},{"x":-1,"y":19,"z":1,"b":"minecraft:iron_block"},{"x":-1,"y":19,"z":2,"b":"minecraft:iron_block"},{"x":-1,"y":19,"z":3,"b":"minecraft:iron_block"},{"x":-1,"y":19,"z":4,"b":"minecraft:iron_block"},{"x":2,"y":20,"z":-3,"b":"minecraft:gold_block"},{"x":2,"y":20,"z":-2,"b":"minecraft:gold_block"},{"x":2,"y":20,"z":-1,"b":"minecraft:gold_block"},{"x":-2,"y":20,"z":0,"b":"minecraft:iron_block"},{"x":-1,"y":20,"z":0,"b":"minecraft:iron_block"},{"x":0,"y":20,"z":0,"b":"minecraft:obsidian"},{"x":1,"y":20,"z":0,"b":"minecraft:gold_block"},{"x":2,"y":20,"z":0,"b":"minecraft:gold_block"},{"x":-2,"y":20,"z":1,"b":"minecraft:iron_block"},{"x":-2,"y":20,"z":2,"b":"minecraft:iron_block"},{"x":-2,"y":20,"z":3,"b":"minecraft:iron_block"},{"x":3,"y":21,"z":-3,"b":"minecraft:gold_block"},{"x":3,"y":21,"z":-2,"b":"minecraft:gold_block"},{"x":3,"y":21,"z":-1,"b":"minecraft:gold_block"},{"x":-3,"y":21,"z":0,"b":"minecraft:iron_block"},{"x":-2,"y":21,"z":0,"b":"minecraft:iron_block"},{"x":-1,"y":21,"z":0,"b":"minecraft:iron_block"},{"x":0,"y":21,"z":0,"b":"minecraft:obsidian"},{"x":1,"y":21,"z":0,"b":"minecraft:gold_block"},{"x":2,"y":21,"z":0,"b":"minecraft:gold_block"},{"x":3,"y":21,"z":0,"b":"minecraft:gold_block"},{"x":-3,"y":21,"z":1,"b":"minecraft:iron_block"},{"x":-3,"y":21,"z":2,"b":"minecraft:iron_block"},{"x":-3,"y":21,"z":3,"b":"minecraft:iron_block"},{"x":3,"y":22,"z":-2,"b":"minecraft:gold_block"},{"x":3,"y":22,"z":-1,"b":"minecraft:gold_block"},{"x":-3,"y":22,"z":0,"b":"minecraft:iron_block"},{"x":-2,"y":22,"z":0,"b":"minecraft:iron_block"},{"x":-1,"y":22,"z":0,"b":"minecraft:iron_block"},{"x":0,"y":22,"z":0,"b":"minecraft:obsidian"},{"x":1,"y":22,"z":0,"b":"minecraft:gold_block"},{"x":2,"y":22,"z":0,"b":"minecraft:gold_block"},{"x":3,"y":22,"z":0,"b":"minecraft:gold_block"},{"x":-3,"y":22,"z":1,"b":"minecraft:iron_block"},{"x":-3,"y":22,"z":2,"b":"minecraft:iron_block"},{"x":4,"y":23,"z":-1,"b":"minecraft:gold_block"},{"x":-4,"y":23,"z":0,"b":"minecraft:iron_block"},{"x":-3,"y":23,"z":0,"b":"minecraft:iron_block"},{"x":-2,"y":23,"z":0,"b":"minecraft:iron_block"},{"x":-1,"y":23,"z":0,"b":"minecraft:iron_block"},{"x":0,"y":23,"z":0,"b":"minecraft:obsidian"},{"x":1,"y":23,"z":0,"b":"minecraft:gold_block"},{"x":2,"y":23,"z":0,"b":"minecraft:gold_block"},{"x":3,"y":23,"z":0,"b":"minecraft:gold_block"},{"x":4,"y":23,"z":0,"b":"minecraft:gold_block"},{"x":-4,"y":23,"z":1,"b":"minecraft:iron_block"},{"x":-4,"y":24,"z":0,"b":"minecraft:iron_block"},{"x":-3,"y":24,"z":0,"b":"minecraft:iron_block"},{"x":-2,"y":24,"z":0,"b":"minecraft:iron_block"},{"x":-1,"y":24,"z":0,"b":"minecraft:iron_block"},{"x":0,"y":24,"z":0,"b":"minecraft:obsidian"},{"x":1,"y":24,"z":0,"b":"minecraft:gold_block"},{"x":2,"y":24,"z":0,"b":"minecraft:gold_block"},{"x":3,"y":24,"z":0,"b":"minecraft:gold_block"},{"x":4,"y":24,"z":0,"b":"minecraft:gold_block"},{"x":-4,"y":25,"z":-1,"b":"minecraft:iron_block"},{"x":-4,"y":25,"z":0,"b":"minecraft:iron_block"},{"x":-3,"y":25,"z":0,"b":"minecraft:iron_block"},{"x":-2,"y":25,"z":0,"b":"minecraft:iron_block"},{"x":-1,"y":25,"z":0,"b":"minecraft:iron_block"},{"x":0,"y":25,"z":0,"b":"minecraft:obsidian"},{"x":1,"y":25,"z":0,"b":"minecraft:gold_block"},{"x":2,"y":25,"z":0,"b":"minecraft:gold_block"},{"x":3,"y":25,"z":0,"b":"minecraft:gold_block"},{"x":4,"y":25,"z":0,"b":"minecraft:gold_block"},{"x":4,"y":25,"z":1,"b":"minecraft:gold_block"},{"x":-3,"y":26,"z":-2,"b":"minecraft:iron_block"},{"x":-3,"y":26,"z":-1,"b":"minecraft:iron_block"},{"x":-3,"y":26,"z":0,"b":"minecraft:iron_block"},{"x":-2,"y":26,"z":0,"b":"minecraft:iron_block"},{"x":-1,"y":26,"z":0,"b":"minecraft:iron_block"},{"x":0,"y":26,"z":0,"b":"minecraft:obsidian"},{"x":1,"y":26,"z":0,"b":"minecraft:gold_block"},{"x":2,"y":26,"z":0,"b":"minecraft:gold_block"},{"x":3,"y":26,"z":0,"b":"minecraft:gold_block"},{"x":3,"y":26,"z":1,"b":"minecraft:gold_block"},{"x":3,"y":26,"z":2,"b":"minecraft:gold_block"},{"x":-3,"y":27,"z":-3,"b":"minecraft:iron_block"},{"x":-3,"y":27,"z":-2,"b":"minecraft:iron_block"},{"x":-3,"y":27,"z":-1,"b":"minecraft:iron_block"},{"x":-3,"y":27,"z":0,"b":"minecraft:iron_block"},{"x":-2,"y":27,"z":0,"b":"minecraft:iron_block"},{"x":-1,"y":27,"z":0,"b":"minecraft:iron_block"},{"x":0,"y":27,"z":0,"b":"minecraft:obsidian"},{"x":1,"y":27,"z":0,"b":"minecraft:gold_block"},{"x":2,"y":27,"z":0,"b":"minecraft:gold_block"},{"x":3,"y":27,"z":0,"b":"minecraft:gold_block"},{"x":3,"y":27,"z":1,"b":"minecraft:gold_block"},{"x":3,"y":27,"z":2,"b":"minecraft:gold_block"},{"x":3,"y":27,"z":3,"b":"minecraft:gold_block"},{"x":-2,"y":28,"z":-3,"b":"minecraft:iron_block"},{"x":-2,"y":28,"z":-2,"b":"minecraft:iron_block"},{"x":-2,"y":28,"z":-1,"b":"minecraft:iron_block"},{"x":-2,"y":28,"z":0,"b":"minecraft:iron_block"},{"x":-1,"y":28,"z":0,"b":"minecraft:iron_block"},{"x":0,"y":28,"z":0,"b":"minecraft:obsidian"},{"x":1,"y":28,"z":0,"b":"minecraft:gold_block"},{"x":2,"y":28,"z":0,"b":"minecraft:gold_block"},{"x":2,"y":28,"z":1,"b":"minecraft:gold_block"},{"x":2,"y":28,"z":2,"b":"minecraft:gold_block"},{"x":2,"y":28,"z":3,"b":"minecraft:gold_block"},{"x":-1,"y":29,"z":-4,"b":"minecraft:iron_block"},{"x":-1,"y":29,"z":-3,"b":"minecraft:iron_block"},{"x":-1,"y":29,"z":-2,"b":"minecraft:iron_block"},{"x":-1,"y":29,"z":-1,"b":"minecraft:iron_block"},{"x":-1,"y":29,"z":0,"b":"minecraft:iron_block"},{"x":0,"y":29,"z":0,"b":"minecraft:obsidian"},{"x":1,"y":29,"z":0,"b":"minecraft:gold_block"},{"x":1,"y":29,"z":1,"b":"minecraft:gold_block"},{"x":1,"y":29,"z":2,"b":"minecraft:gold_block"},{"x":1,"y":29,"z":3,"b":"minecraft:gold_block"},{"x":1,"y":29,"z":4,"b":"minecraft:gold_block"},{"x":0,"y":30,"z":-4,"b":"minecraft:iron_block"},{"x":0,"y":30,"z":-3,"b":"minecraft:iron_block"},{"x":0,"y":30,"z":-2,"b":"minecraft:iron_block"},{"x":0,"y":30,"z":-1,"b":"minecraft:iron_block"},{"x":0,"y":30,"z":0,"b":"minecraft:obsidian"},{"x":0,"y":30,"z":1,"b":"minecraft:gold_block"},{"x":0,"y":30,"z":2,"b":"minecraft:gold_block"},{"x":0,"y":30,"z":3,"b":"minecraft:gold_block"},{"x":0,"y":30,"z":4,"b":"minecraft:gold_block"},{"x":1,"y":31,"z":-4,"b":"minecraft:iron_block"},{"x":1,"y":31,"z":-3,"b":"minecraft:iron_block"},{"x":1,"y":31,"z":-2,"b":"minecraft:iron_block"},{"x":1,"y":31,"z":-1,"b":"minecraft:iron_block"},{"x":-1,"y":31,"z":0,"b":"minecraft:gold_block"},{"x":0,"y":31,"z":0,"b":"minecraft:obsidian"},{"x":1,"y":31,"z":0,"b":"minecraft:iron_block"},{"x":-1,"y":31,"z":1,"b":"minecraft:gold_block"},{"x":-1,"y":31,"z":2,"b":"minecraft:gold_block"},{"x":-1,"y":31,"z":3,"b":"minecraft:gold_block"},{"x":-1,"y":31,"z":4,"b":"minecraft:gold_block"},{"x":2,"y":32,"z":-3,"b":"minecraft:iron_block"},{"x":2,"y":32,"z":-2,"b":"minecraft:iron_block"},{"x":2,"y":32,"z":-1,"b":"minecraft:iron_block"},{"x":-2,"y":32,"z":0,"b":"minecraft:gold_block"},{"x":-1,"y":32,"z":0,"b":"minecraft:gold_block"},{"x":0,"y":32,"z":0,"b":"minecraft:obsidian"},{"x":1,"y":32,"z":0,"b":"minecraft:iron_block"},{"x":2,"y":32,"z":0,"b":"minecraft:iron_block"},{"x":-2,"y":32,"z":1,"b":"minecraft:gold_block"},{"x":-2,"y":32,"z":2,"b":"minecraft:gold_block"},{"x":-2,"y":32,"z":3,"b":"minecraft:gold_block"},{"x":3,"y":33,"z":-3,"b":"minecraft:iron_block"},{"x":3,"y":33,"z":-2,"b":"minecraft:iron_block"},{"x":3,"y":33,"z":-1,"b":"minecraft:iron_block"},{"x":-3,"y":33,"z":0,"b":"minecraft:gold_block"},{"x":-2,"y":33,"z":0,"b":"minecraft:gold_block"},{"x":-1,"y":33,"z":0,"b":"minecraft:gold_block"},{"x":0,"y":33,"z":0,"b":"minecraft:obsidian"},{"x":1,"y":33,"z":0,"b":"minecraft:iron_block"},{"x":2,"y":33,"z":0,"b":"minecraft:iron_block"},{"x":3,"y":33,"z":0,"b":"minecraft:iron_block"},{"x":-3,"y":33,"z":1,"b":"minecraft:gold_block"},{"x":-3,"y":33,"z":2,"b":"minecraft:gold_block"},{"x":-3,"y":33,"z":3,"b":"minecraft:gold_block"},{"x":3,"y":34,"z":-2,"b":"minecraft:iron_block"},{"x":3,"y":34,"z":-1,"b":"minecraft:iron_block"},{"x":-3,"y":34,"z":0,"b":"minecraft:gold_block"},{"x":-2,"y":34,"z":0,"b":"minecraft:gold_block"},{"x":-1,"y":34,"z":0,"b":"minecraft:gold_block"},{"x":0,"y":34,"z":0,"b":"minecraft:obsidian"},{"x":1,"y":34,"z":0,"b":"minecraft:iron_block"},{"x":2,"y":34,"z":0,"b":"minecraft:iron_block"},{"x":3,"y":34,"z":0,"b":"minecraft:iron_block"},{"x":-3,"y":34,"z":1,"b":"minecraft:gold_block"},{"x":-3,"y":34,"z":2,"b":"minecraft:gold_block"},{"x":4,"y":35,"z":-1,"b":"minecraft:iron_block"},{"x":-4,"y":35,"z":0,"b":"minecraft:gold_block"},{"x":-3,"y":35,"z":0,"b":"minecraft:gold_block"},{"x":-2,"y":35,"z":0,"b":"minecraft:gold_block"},{"x":-1,"y":35,"z":0,"b":"minecraft:gold_block"},{"x":0,"y":35,"z":0,"b":"minecraft:obsidian"},{"x":1,"y":35,"z":0,"b":"minecraft:iron_block"},{"x":2,"y":35,"z":0,"b":"minecraft:iron_block"},{"x":3,"y":35,"z":0,"b":"minecraft:iron_block"},{"x":4,"y":35,"z":0,"b":"minecraft:iron_block"},{"x":-4,"y":35,"z":1,"b":"minecraft:gold_block"},{"x":-4,"y":36,"z":0,"b":"minecraft:gold_block"},{"x":-3,"y":36,"z":0,"b":"minecraft:gold_block"},{"x":-2,"y":36,"z":0,"b":"minecraft:gold_block"},{"x":-1,"y":36,"z":0,"b":"minecraft:gold_block"},{"x":0,"y":36,"z":0,"b":"minecraft:obsidian"},{"x":1,"y":36,"z":0,"b":"minecraft:iron_block"},{"x":2,"y":36,"z":0,"b":"minecraft:iron_block"},{"x":3,"y":36,"z":0,"b":"minecraft:iron_block"},{"x":4,"y":36,"z":0,"b":"minecraft:iron_block"},{"x":-4,"y":37,"z":-1,"b":"minecraft:gold_block"},{"x":-4,"y":37,"z":0,"b":"minecraft:gold_block"},{"x":-3,"y":37,"z":0,"b":"minecraft:gold_block"},{"x":-2,"y":37,"z":0,"b":"minecraft:gold_block"},{"x":-1,"y":37,"z":0,"b":"minecraft:gold_block"},{"x":0,"y":37,"z":0,"b":"minecraft:obsidian"},{"x":1,"y":37,"z":0,"b":"minecraft:iron_block"},{"x":2,"y":37,"z":0,"b":"minecraft:iron_block"},{"x":3,"y":37,"z":0,"b":"minecraft:iron_block"},{"x":4,"y":37,"z":0,"b":"minecraft:iron_block"},{"x":4,"y":37,"z":1,"b":"minecraft:iron_block"},{"x":-3,"y":38,"z":-2,"b":"minecraft:gold_block"},{"x":-3,"y":38,"z":-1,"b":"minecraft:gold_block"},{"x":-3,"y":38,"z":0,"b":"minecraft:gold_block"},{"x":-2,"y":38,"z":0,"b":"minecraft:gold_block"},{"x":-1,"y":38,"z":0,"b":"minecraft:gold_block"},{"x":0,"y":38,"z":0,"b":"minecraft:obsidian"},{"x":1,"y":38,"z":0,"b":"minecraft:iron_block"},{"x":2,"y":38,"z":0,"b":"minecraft:iron_block"},{"x":3,"y":38,"z":0,"b":"minecraft:iron_block"},{"x":3,"y":38,"z":1,"b":"minecraft:iron_block"},{"x":3,"y":38,"z":2,"b":"minecraft:iron_block"},{"x":-3,"y":39,"z":-3,"b":"minecraft:gold_block"},{"x":-3,"y":39,"z":-2,"b":"minecraft:gold_block"},{"x":-3,"y":39,"z":-1,"b":"minecraft:gold_block"},{"x":-3,"y":39,"z":0,"b":"minecraft:gold_block"},{"x":-2,"y":39,"z":0,"b":"minecraft:gold_block"},{"x":-1,"y":39,"z":0,"b":"minecraft:gold_block"},{"x":0,"y":39,"z":0,"b":"minecraft:obsidian"},{"x":1,"y":39,"z":0,"b":"minecraft:iron_block"},{"x":2,"y":39,"z":0,"b":"minecraft:iron_block"},{"x":3,"y":39,"z":0,"b":"minecraft:iron_block"},{"x":3,"y":39,"z":1,"b":"minecraft:iron_block"},{"x":3,"y":39,"z":2,"b":"minecraft:iron_block"},{"x":3,"y":39,"z":3,"b":"minecraft:iron_block"},{"x":-2,"y":40,"z":-3,"b":"minecraft:gold_block"},{"x":-2,"y":40,"z":-2,"b":"minecraft:gold_block"},{"x":-2,"y":40,"z":-1,"b":"minecraft:gold_block"},{"x":-2,"y":40,"z":0,"b":"minecraft:gold_block"},{"x":-1,"y":40,"z":0,"b":"minecraft:gold_block"},{"x":0,"y":40,"z":0,"b":"minecraft:obsidian"},{"x":1,"y":40,"z":0,"b":"minecraft:iron_block"},{"x":2,"y":40,"z":0,"b":"minecraft:iron_block"},{"x":2,"y":40,"z":1,"b":"minecraft:iron_block"},{"x":2,"y":40,"z":2,"b":"minecraft:iron_block"},{"x":2,"y":40,"z":3,"b":"minecraft:iron_block"},{"x":-1,"y":41,"z":-4,"b":"minecraft:gold_block"},{"x":-1,"y":41,"z":-3,"b":"minecraft:gold_block"},{"x":-1,"y":41,"z":-2,"b":"minecraft:gold_block"},{"x":-1,"y":41,"z":-1,"b":"minecraft:gold_block"},{"x":-1,"y":41,"z":0,"b":"minecraft:gold_block"},{"x":0,"y":41,"z":0,"b":"minecraft:obsidian"},{"x":1,"y":41,"z":0,"b":"minecraft:iron_block"},{"x":1,"y":41,"z":1,"b":"minecraft:iron_block"},{"x":1,"y":41,"z":2,"b":"minecraft:iron_block"},{"x":1,"y":41,"z":3,"b":"minecraft:iron_block"},{"x":1,"y":41,"z":4,"b":"minecraft:iron_block"},{"x":0,"y":42,"z":-4,"b":"minecraft:gold_block"},{"x":0,"y":42,"z":-3,"b":"minecraft:gold_block"},{"x":0,"y":42,"z":-2,"b":"minecraft:gold_block"},{"x":0,"y":42,"z":-1,"b":"minecraft:gold_block"},{"x":0,"y":42,"z":0,"b":"minecraft:obsidian"},{"x":0,"y":42,"z":1,"b":"minecraft:iron_block"},{"x":0,"y":42,"z":2,"b":"minecraft:iron_block"},{"x":0,"y":42,"z":3,"b":"minecraft:iron_block"},{"x":0,"y":42,"z":4,"b":"minecraft:iron_block"},{"x":1,"y":43,"z":-4,"b":"minecraft:gold_block"},{"x":1,"y":43,"z":-3,"b":"minecraft:gold_block"},{"x":1,"y":43,"z":-2,"b":"minecraft:gold_block"},{"x":1,"y":43,"z":-1,"b":"minecraft:gold_block"},{"x":-1,"y":43,"z":0,"b":"minecraft:iron_block"},{"x":0,"y":43,"z":0,"b":"minecraft:obsidian"},{"x":1,"y":43,"z":0,"b":"minecraft:gold_block"},{"x":-1,"y":43,"z":1,"b":"minecraft:iron_block"},{"x":-1,"y":43,"z":2,"b":"minecraft:iron_block"},{"x":-1,"y":43,"z":3,"b":"minecraft:iron_block"},{"x":-1,"y":43,"z":4,"b":"minecraft:iron_block"},{"x":2,"y":44,"z":-3,"b":"minecraft:gold_block"},{"x":2,"y":44,"z":-2,"b":"minecraft:gold_block"},{"x":2,"y":44,"z":-1,"b":"minecraft:gold_block"},{"x":-2,"y":44,"z":0,"b":"minecraft:iron_block"},{"x":-1,"y":44,"z":0,"b":"minecraft:iron_block"},{"x":0,"y":44,"z":0,"b":"minecraft:obsidian"},{"x":1,"y":44,"z":0,"b":"minecraft:gold_block"},{"x":2,"y":44,"z":0,"b":"minecraft:gold_block"},{"x":-2,"y":44,"z":1,"b":"minecraft:iron_block"},{"x":-2,"y":44,"z":2,"b":"minecraft:iron_block"},{"x":-2,"y":44,"z":3,"b":"minecraft:iron_block"},{"x":3,"y":45,"z":-3,"b":"minecraft:gold_block"},{"x":3,"y":45,"z":-2,"b":"minecraft:gold_block"},{"x":3,"y":45,"z":-1,"b":"minecraft:gold_block"},{"x":-3,"y":45,"z":0,"b":"minecraft:iron_block"},{"x":-2,"y":45,"z":0,"b":"minecraft:iron_block"},{"x":-1,"y":45,"z":0,"b":"minecraft:iron_block"},{"x":0,"y":45,"z":0,"b":"minecraft:obsidian"},{"x":1,"y":45,"z":0,"b":"minecraft:gold_block"},{"x":2,"y":45,"z":0,"b":"minecraft:gold_block"},{"x":3,"y":45,"z":0,"b":"minecraft:gold_block"},{"x":-3,"y":45,"z":1,"b":"minecraft:iron_block"},{"x":-3,"y":45,"z":2,"b":"minecraft:iron_block"},{"x":-3,"y":45,"z":3,"b":"minecraft:iron_block"},{"x":3,"y":46,"z":-2,"b":"minecraft:gold_block"},{"x":3,"y":46,"z":-1,"b":"minecraft:gold_block"},{"x":-3,"y":46,"z":0,"b":"minecraft:iron_block"},{"x":-2,"y":46,"z":0,"b":"minecraft:iron_block"},{"x":-1,"y":46,"z":0,"b":"minecraft:iron_block"},{"x":0,"y":46,"z":0,"b":"minecraft:obsidian"},{"x":1,"y":46,"z":0,"b":"minecraft:gold_block"},{"x":2,"y":46,"z":0,"b":"minecraft:gold_block"},{"x":3,"y":46,"z":0,"b":"minecraft:gold_block"},{"x":-3,"y":46,"z":1,"b":"minecraft:iron_block"},{"x":-3,"y":46,"z":2,"b":"minecraft:iron_block"},{"x":4,"y":47,"z":-1,"b":"minecraft:gold_block"},{"x":-4,"y":47,"z":0,"b":"minecraft:iron_block"},{"x":-3,"y":47,"z":0,"b":"minecraft:iron_block"},{"x":-2,"y":47,"z":0,"b":"minecraft:iron_block"},{"x":-1,"y":47,"z":0,"b":"minecraft:iron_block"},{"x":0,"y":47,"z":0,"b":"minecraft:obsidian"},{"x":1,"y":47,"z":0,"b":"minecraft:gold_block"},{"x":2,"y":47,"z":0,"b":"minecraft:gold_block"},{"x":3,"y":47,"z":0,"b":"minecraft:gold_block"},{"x":4,"y":47,"z":0,"b":"minecraft:gold_block"},{"x":-4,"y":47,"z":1,"b":"minecraft:iron_block"},{"x":-1,"y":48,"z":-1,"b":"minecraft:diamond_block"},{"x":0,"y":48,"z":-1,"b":"minecraft:diamond_block"},{"x":1,"y":48,"z":-1,"b":"minecraft:diamond_block"},{"x":-1,"y":48,"z":0,"b":"minecraft:diamond_block"},{"x":0,"y":48,"z":0,"b":"minecraft:diamond_block"},{"x":1,"y":48,"z":0,"b":"minecraft:diamond_block"},{"x":-1,"y":48,"z":1,"b":"minecraft:diamond_block"},{"x":0,"y":48,"z":1,"b":"minecraft:diamond_block"},{"x":1,"y":48,"z":1,"b":"minecraft:diamond_block"},{"x":0,"y":49,"z":0,"b":"minecraft:diamond_block"}]}
